Workbook

Sheet เริ่มที่นี่
A1: MGS Document Hub — โครงสร้างระบบหลังบ้าน
A2: ไฟล์นี้คือโครงสร้างหลังบ้านทั้งหมดในที่เดียว สำหรับให้ทีมตรวจและแก้ก่อนเริ่มสร้างจริง · แก้ในไฟล์นี้ได้เลย แล้วส่งกลับมา ระบบจะสร้างตามไฟล์นี้
A4: สีในไฟล์นี้หมายถึงอะไร
A5: เหลือง = แก้ได้ | B5: ช่องที่ตั้งใจให้ทีมแก้ — เกณฑ์ SLA อัตราภาษี วงเงินอนุมัติ ชื่อฟิลด์ ฯลฯ
A6: เทา = อ้างอิง | B6: ค่าที่ระบบใช้เป็นคีย์หรือคำนวณเอง แก้ได้แต่ต้องบอกก่อน เพราะกระทบโค้ด
A7: ฟ้า = เพิ่มใหม่ล่าสุด | B7: ตาราง Price_Requests / Quotations / Payment_Requests / Doc_Bundles และคอลัมน์เรื่องซื้อเงินสด-ไดรฟ์กลาง-รวมไฟล์ ที่เพิ่งเพิ่ม ยังไม่ผ่านตาทีม
A8: แดง = ต้องตัดสินใจ | B8: ตัวเลขที่ผมตั้งค่าเริ่มต้นไว้เอง ต้องให้ทีมยืนยันก่อนขึ้นระบบ
A10: แต่ละแท็บใช้ทำอะไร
A11: แท็บ | B11: ใช้ทำอะไร | C11: ใครควรตรวจ
A12: สารบัญตาราง | B12: รายชื่อตารางทั้งหมด หน้าที่ และจำนวนคอลัมน์ (นับอัตโนมัติ) | C12: IT + หัวหน้าทุกแผนก
A13: พจนานุกรมข้อมูล | B13: ทุกคอลัมน์ของทุกตาราง — ชนิด บังคับไหม มาจากไหน | C13: IT + แผนกเจ้าของข้อมูล
A14: ขั้นตอนงาน | B14: 17 ขั้นตอน เจ้าของ SLA เฟส — แก้ SLA ได้ที่นี่ | C14: หัวหน้าทุกแผนก
A15: เอกสารที่ต้องมี | B15: เอกสารบังคับต่อ PO ใครเป็นเจ้าของใบไหน | C15: SR / QC / WH / AC
A16: กฎตรวจสอบ | B16: กฎที่ระบบใช้บล็อก/เตือนก่อนบันทึก — แก้เกณฑ์ได้ (ดูจำนวนจริงในสรุปด้านล่าง) | C16: AC เป็นหลัก
A17: สิทธิ์แต่ละแผนก | B17: ใครสร้าง/ดู/แก้/อนุมัติอะไรได้ | C17: หัวหน้าทุกแผนก + ผู้ตรวจสอบ
A18: การแจ้งเตือน | B18: เหตุการณ์ไหนแจ้งใคร ช่องทางไหน เมื่อไหร่ | C18: หัวหน้าทุกแผนก
A19: สถานะ | B19: สถานะทั้งหมดของแต่ละเอกสาร และเปลี่ยนไปไหนได้บ้าง | C19: IT + AC
A20: ค่าตั้งต้น | B20: ตัวเลขทั้งหมดที่ปรับได้อยู่ในแท็บเดียว | C20: AC + หัวหน้าทุกแผนก
A21: เชื่อมต่อ B1 | B21: ฟิลด์ไหนดึงจากตารางไหนของ Business One | C21: ผู้ดูแล B1
A22: ประเด็นค้าง | B22: สิ่งที่ยังต้องตัดสินใจก่อนขึ้นระบบ พร้อมผู้รับผิดชอบ | C22: ทุกคน — ดูแท็บนี้ก่อน
A24: สรุปตัวเลข ณ ตอนนี้
A25: จำนวนตารางทั้งหมด | B25: =COUNTA(สารบัญตาราง!$B$5:$B$24)
A26: จำนวนคอลัมน์ทั้งหมด | B26: =COUNTA(พจนานุกรมข้อมูล!$B$5:$B$394)
A27: ขั้นตอนงาน | B27: =COUNTA(ขั้นตอนงาน!$B$5:$B$21)
A28: เอกสารบังคับต่อ PO | B28: =COUNTIF(เอกสารที่ต้องมี!$E$5:$E$13,"บังคับ")
A29: กฎตรวจสอบ | B29: =COUNTA(กฎตรวจสอบ!$A$5:$A$48)
A30: ค่าตั้งต้นที่ปรับได้ | B30: =COUNTA(ค่าตั้งต้น!$A$5:$A$46)
A31: ประเด็นที่ยังรอตัดสินใจ | B31: =COUNTIF(ประเด็นค้าง!$G$5:$G$45,"รอตัดสินใจ")
A32: ประเด็นที่ตัดสินใจแล้ว | B32: =COUNTIF(ประเด็นค้าง!$G$5:$G$45,"ตัดสินใจแล้ว")
A34: วิธีใช้ไฟล์นี้
A35: 1. เปิดแท็บ «ประเด็นค้าง» ก่อน — เป็นรายการที่ผมตั้งค่าเริ่มต้นไว้เองและต้องให้ทีมยืนยัน
A36: 2. แต่ละแผนกดูแท็บที่เกี่ยวกับตัวเอง (ดูตารางด้านบนว่าใครควรตรวจแท็บไหน)
A37: 3. แก้ได้เฉพาะช่องพื้นเหลือง · ถ้าจะแก้ช่องเทา ให้เขียนหมายเหตุไว้ในคอลัมน์สุดท้ายของแถวนั้น
A38: 4. ช่องไหนไม่เห็นด้วย ให้พิมพ์ทับได้เลย ไม่ต้องกลัวผิด — ไฟล์นี้มีไว้ให้แก้
A39: 5. ส่งไฟล์กลับมา ระบบจะถูกสร้างตามไฟล์นี้ ไม่ใช่ตามเอกสารเดิม
A41: สำคัญ: ไฟล์นี้เป็น «ต้นฉบับ» ของโครงสร้างหลังบ้าน — ที่ตกลงกันในไฟล์นี้คือสิ่งที่จะถูกสร้าง ถ้าแก้ในไฟล์นี้แล้วไม่ตรงกับเอกสาร .md ให้ยึดไฟล์นี้

Sheet รายการเลือก (ระบบ)
A1: DTYPE | B1: YN | C1: SRC | D1: DEPT | E1: PHASE | F1: SEV | G1: RULEST | H1: TBLST | I1: ISSUEST | J1: PRIO | K1: TIER
A2: UUID | B2: บังคับ | C2: ดึงจาก B1 | D2: SR | E2: BUY | F2: บล็อก | G2: ใช้งาน | H2: ยืนยันแล้ว | I2: รอตัดสินใจ | J2: สูง | K2: 1 ในเว็บ
A3: TEXT | B3: ไม่บังคับ | C3: คนกรอก | D3: QC | E3: RECV | F3: เตือน | G3: รอทีมยืนยันเกณฑ์ | H3: รอทีมตรวจ | I3: ตัดสินใจแล้ว | J3: กลาง | K3: 2 Lark
A4: NUMBER | C4: ระบบสร้าง/คำนวณ | D4: LS | E4: AP | F4: บันทึกเฉย ๆ | G4: ปิดใช้งาน | H4: เพิ่มใหม่ล่าสุด | I4: ไม่เกี่ยวข้องแล้ว | J4: ต่ำ | K4: 3 อีเมล
A5: DATE | C5: คัดลอกจากเอกสารต้นทาง | D5: WH | E5: PAY | K5: 2 Lark + 3 อีเมล
A6: DATETIME | D6: AC | K6: 1 + 2
A7: BOOLEAN | D7: GM | K7: 1 + 2 + 3
A8: ENUM | D8: IT/แอดมิน
A9: FILE_ID | D9: ระบบ
A10: JSON

Sheet สารบัญตาราง
A1: สารบัญตาราง
A2: ตารางทั้งหมดในฐานข้อมูล — คอลัมน์ «จำนวนคอลัมน์» นับจากแท็บพจนานุกรมข้อมูลอัตโนมัติ
A4: # | B4: ตาราง | C4: หน้าที่ | D4: จำนวนคอลัมน์ | E4: โตเร็วแค่ไหน | F4: สถานะ | G4: หมายเหตุ / ที่ทีมอยากแก้
A5: 1 | B5: Purchase_Orders | C5: 1 แถว = 1 PO ตั้งแต่เปิดจนปิดบัญชี | D5: =COUNTIF(พจนานุกรมข้อมูล!$A$5:$A$394,$B5) | E5: ~600 แถว/ปี | F5: ยืนยันแล้ว
A6: 2 | B6: PO_Payments | C6: งวดจ่ายของแต่ละ PO (1 PO จ่ายได้หลายงวด) | D6: =COUNTIF(พจนานุกรมข้อมูล!$A$5:$A$394,$B6) | E6: ~900 แถว/ปี | F6: ยืนยันแล้ว
A7: 3 | B7: Doc_Checklist | C7: เอกสารที่ต้องมีต่อ PO และสถานะแต่ละใบ | D7: =COUNTIF(พจนานุกรมข้อมูล!$A$5:$A$394,$B7) | E7: ~4,800 แถว/ปี | F7: ยืนยันแล้ว
A8: 4 | B8: Documents | C8: ไฟล์จริงทุกเวอร์ชันใน Drive | D8: =COUNTIF(พจนานุกรมข้อมูล!$A$5:$A$394,$B8) | E8: ~5,000 แถว/ปี | F8: ยืนยันแล้ว
A9: 5 | B9: Approvals | C9: การอนุมัติและลงนามทุกจุด (PO / จ่าย / เคลม / รหัสสินค้า) | D9: =COUNTIF(พจนานุกรมข้อมูล!$A$5:$A$394,$B9) | E9: ~2,000 แถว/ปี | F9: ยืนยันแล้ว
A10: 6 | B10: Stage_Log | C10: บันทึกทุกการเปลี่ยนสถานะ — เขียนเพิ่มเท่านั้น | D10: =COUNTIF(พจนานุกรมข้อมูล!$A$5:$A$394,$B10) | E10: ~10,200 แถว/ปี | F10: ยืนยันแล้ว | G10: ที่มาของสถานะ คอขวด และ KPI ทุกตัว · แยกแท็บต่อปี
A11: 7 | B11: Notifications | C11: คิวแจ้งเตือน Lark / อีเมล | D11: =COUNTIF(พจนานุกรมข้อมูล!$A$5:$A$394,$B11) | E11: ~25,000 แถว/ปี | F11: ยืนยันแล้ว | G11: แยกแท็บต่อปี
A12: 8 | B12: Issues | C12: ปัญหาที่ผู้ใช้กดแจ้งจากหน้าจอ | D12: =COUNTIF(พจนานุกรมข้อมูล!$A$5:$A$394,$B12) | E12: ~200 แถว/ปี | F12: ยืนยันแล้ว
A13: 9 | B13: Claims | C13: ใบเคลม/ร้องเรียน ตามฟอร์ม QC-F006 | D13: =COUNTIF(พจนานุกรมข้อมูล!$A$5:$A$394,$B13) | E13: ~60 แถว/ปี | F13: รอทีมตรวจ | G13: ยังรอฟิลด์จริงของ «ส่วนที่ 3» ในฟอร์ม (หน้า 2–3 เป็นภาพสแกน)
A14: 10 | B14: ItemCode_Requests | C14: ใบขอเปิดรหัสสินค้าใหม่ | D14: =COUNTIF(พจนานุกรมข้อมูล!$A$5:$A$394,$B14) | E14: ~80 แถว/ปี | F14: รอทีมตรวจ | G14: รอดูว่ามีฟอร์มควบคุมเดิมอยู่แล้วหรือไม่
A15: 11 | B15: Price_Requests | C15: ใบขอราคา — จุดเริ่มก่อนมี PO | D15: =COUNTIF(พจนานุกรมข้อมูล!$A$5:$A$394,$B15) | E15: ~700 แถว/ปี | F15: เพิ่มใหม่ล่าสุด | G15: เพิ่มรอบล่าสุด แก้ปัญหาใบขอราคาดึงไปทำใบเสนอราคาไม่ได้
A16: 12 | B16: Quotations | C16: ใบเสนอราคาจากผู้ขาย (1 ใบขอราคา → หลายใบ) | D16: =COUNTIF(พจนานุกรมข้อมูล!$A$5:$A$394,$B16) | E16: ~1,800 แถว/ปี | F16: เพิ่มใหม่ล่าสุด | G16: เพิ่มรอบล่าสุด
A17: 13 | B17: Stage_Templates | C17: นิยามขั้นตอนต่อ module — เพิ่ม module = เพิ่มแถว | D17: =COUNTIF(พจนานุกรมข้อมูล!$A$5:$A$394,$B17) | E17: ~20 แถว/module | F17: ยืนยันแล้ว
A18: 14 | B18: Doc_Templates | C18: นิยามเอกสารที่ต้องมีต่อ module | D18: =COUNTIF(พจนานุกรมข้อมูล!$A$5:$A$394,$B18) | E18: ~10 แถว/module | F18: ยืนยันแล้ว
A19: 15 | B19: Users | C19: ผู้ใช้ แผนก สิทธิ์ และ lark_user_id | D19: =COUNTIF(พจนานุกรมข้อมูล!$A$5:$A$394,$B19) | E19: ~40 แถว | F19: รอทีมตรวจ | G19: ต้องมี lark_user_id ครบทุกคน เพราะใช้ Lark ช่องทางเดียว
A20: 16 | B20: Suppliers | C20: ผู้ขาย — บางมาก เพราะ master จริงอยู่ใน B1 | D20: =COUNTIF(พจนานุกรมข้อมูล!$A$5:$A$394,$B20) | E20: ~150 แถว | F20: ยืนยันแล้ว
A21: 17 | B21: Config / Lookups | C21: ค่าตั้งต้นและรายการ dropdown | D21: =COUNTIF(พจนานุกรมข้อมูล!$A$5:$A$394,$B21) | E21: ~120 แถว | F21: ยืนยันแล้ว | G21: จริง ๆ เป็น 2 แท็บ (Config กับ Lookups) นับรวมเป็น 1 รายการ
A22: 18 | B22: Sync_Log | C22: บันทึกทุกรอบที่ดึงข้อมูลจาก B1 | D22: =COUNTIF(พจนานุกรมข้อมูล!$A$5:$A$394,$B22) | E22: ~17,500 แถว/ปี | F22: ยืนยันแล้ว | G22: แยกแท็บต่อปี
A23: 19 | B23: Payment_Requests | C23: คำขอทำจ่ายที่จัดซื้อส่งให้หัวหน้า (1 งวดขอได้หลายรอบ) | D23: =COUNTIF(พจนานุกรมข้อมูล!$A$5:$A$394,$B23) | E23: ~1,100 แถว/ปี | F23: เพิ่มใหม่ล่าสุด | G23: เพิ่มรอบล่าสุด — ยอดเงินและ Effective date เป็นช่องบังคับ
A24: 20 | B24: Doc_Bundles | C24: ชุดเอกสารรวมเล่มที่สร้างอัตโนมัติเมื่อปิดรายการ | D24: =COUNTIF(พจนานุกรมข้อมูล!$A$5:$A$394,$B24) | E24: ~660 แถว/ปี | F24: เพิ่มใหม่ล่าสุด | G24: เพิ่มรอบล่าสุด — 1 รายการ = 1 ชุด
B26: หมายเหตุ: เอกสาร .md ระบุจำนวนตารางไม่ตรงกัน (07 บอก 15, 09 บอก 16, 11 บอก 17) เพราะเขียนคนละรอบ — ตัวเลขจริงคือ 20 รายการตามตารางนี้ (เพิ่ม Payment_Requests และ Doc_Bundles รอบล่าสุด) ให้ยึดไฟล์นี้

Sheet พจนานุกรมข้อมูล
A1: พจนานุกรมข้อมูล
A2: ทุกคอลัมน์ของทุกตาราง · «มาจากไหน» สำคัญที่สุด — บอกว่าคนต้องพิมพ์เองหรือระบบดึงให้
A4: ตาราง | B4: คอลัมน์ | C4: ชนิด | D4: บังคับ | E4: คีย์ | F4: ค่าที่เป็นไปได้ / รูปแบบ | G4: คำอธิบาย | H4: มาจากไหน | I4: หมายเหตุของทีม
A5: Purchase_Orders | B5: po_id | C5: UUID | D5: บังคับ | E5: PK | F5: UUID | G5: คีย์ภายใน ไม่แสดงให้ผู้ใช้เห็น | H5: ระบบสร้าง/คำนวณ
A6: Purchase_Orders | B6: po_no | C6: TEXT | D6: บังคับ | E6: UQ | F6: PO-26-0042 | G6: เลขที่ผู้ใช้เห็นและใช้อ้างอิงกันทุกแผนก | H6: ระบบสร้าง/คำนวณ
A7: Purchase_Orders | B7: module | C7: ENUM | D7: บังคับ | F7: DOMESTIC_FOOD / IMPORT_FOOD / SOLAR | G7: ตัวกำหนดว่าใช้ template ขั้นตอนชุดไหน | H7: ระบบสร้าง/คำนวณ
A8: Purchase_Orders | B8: sap_doc_entry | C8: NUMBER | D8: ไม่บังคับ | E8: FK | F8: OPOR.DocEntry | G8: คีย์จริงของ PO ใน B1 — ใช้จับคู่ตอนดึงข้อมูล | H8: ดึงจาก B1
A9: Purchase_Orders | B9: sap_doc_num | C9: TEXT | D9: ไม่บังคับ | F9: OPOR.DocNum เช่น 10245 | G9: เลข PO ที่คนอ่าน (ต่างจาก DocEntry) | H9: ดึงจาก B1
A10: Purchase_Orders | B10: supplier_code | C10: TEXT | D10: ไม่บังคับ | E10: FK | F10: OCRD.CardCode | G10: รหัสผู้ขาย | H10: ดึงจาก B1
A11: Purchase_Orders | B11: supplier_name | C11: TEXT | D11: ไม่บังคับ | F11: OCRD.CardName | G11: เก็บชื่อซ้ำไว้ไม่ให้ประวัติเปลี่ยนเมื่อ master เปลี่ยน | H11: ดึงจาก B1
A12: Purchase_Orders | B12: item_summary | C12: TEXT | D12: บังคับ | F12: กุ้งแช่แข็ง 16/20 | G12: คำอธิบายสั้นให้จำ PO ได้ | H12: คัดลอกจากเอกสารต้นทาง
A13: Purchase_Orders | B13: qty_summary | C13: TEXT | D13: ไม่บังคับ | F13: 500 KG | G13: จำนวนรวมแบบอ่านง่าย | H13: ดึงจาก B1
A14: Purchase_Orders | B14: currency | C14: TEXT | D14: บังคับ | F14: THB | G14: สกุลเงินของ PO | H14: ดึงจาก B1
A15: Purchase_Orders | B15: total_amount | C15: NUMBER | D15: บังคับ | F15: 130000.00 | G15: มูลค่า PO | H15: ดึงจาก B1
A16: Purchase_Orders | B16: payment_terms_code | C16: TEXT | D16: ไม่บังคับ | E16: FK | F16: OCTG.GroupNum | G16: เงื่อนไขชำระจาก B1 — ใช้สร้างงวดจ่ายอัตโนมัติ | H16: ดึงจาก B1
A17: Purchase_Orders | B17: payment_terms_name | C17: TEXT | D17: ไม่บังคับ | F17: เครดิต 30 วัน | G17: ชื่อเงื่อนไขชำระแบบอ่านง่าย | H17: ดึงจาก B1
A18: Purchase_Orders | B18: owner_email | C18: TEXT | D18: บังคับ | E18: FK | F18: Users.email | G18: SR ผู้ดูแล PO นี้ | H18: คนกรอก
A19: Purchase_Orders | B19: effective_date | C19: DATE | D19: ไม่บังคับ | G19: วันที่มีผล ที่เดิม SR ต้องแจ้ง AC ทางเมล | H19: คนกรอก
A20: Purchase_Orders | B20: expected_delivery_date | C20: DATE | D20: ไม่บังคับ | G20: วันนัดรับของ | H20: คนกรอก
A21: Purchase_Orders | B21: current_stage | C21: TEXT | D21: บังคับ | F21: QC_INCOMING | G21: ขั้นตอนที่ค้างอยู่ตอนนี้ | H21: ระบบสร้าง/คำนวณ
A22: Purchase_Orders | B22: current_owner_email | C22: TEXT | D22: บังคับ | E22: FK | F22: Users.email | G22: ใครถืองานอยู่ตอนนี้ — หัวใจของหน้าหลัก | H22: ระบบสร้าง/คำนวณ
A23: Purchase_Orders | B23: stage_due_at | C23: DATETIME | D23: ไม่บังคับ | G23: กำหนดเสร็จของขั้นปัจจุบัน คำนวณจาก SLA | H23: ระบบสร้าง/คำนวณ
A24: Purchase_Orders | B24: status | C24: ENUM | D24: บังคับ | F24: ACTIVE / COMPLETED / CANCELLED | G24: ใช้แยกแท็บกำลังดำเนินการ/เสร็จสิ้น/ยกเลิก | H24: ระบบสร้าง/คำนวณ
A25: Purchase_Orders | B25: has_open_claim | C25: BOOLEAN | D25: บังคับ | F25: TRUE / FALSE | G25: ถ้า TRUE = ปิด PO ไม่ได้ และงวดจ่ายถูกล็อก | H25: ระบบสร้าง/คำนวณ
A26: Purchase_Orders | B26: doc_complete | C26: BOOLEAN | D26: บังคับ | F26: TRUE / FALSE | G26: เอกสารบังคับครบหรือยัง | H26: ระบบสร้าง/คำนวณ
A27: Purchase_Orders | B27: match_ready | C27: BOOLEAN | D27: บังคับ | F27: TRUE / FALSE | G27: ตรวจ 3 ทางผ่านหรือยัง | H27: ระบบสร้าง/คำนวณ
A28: Purchase_Orders | B28: match_diff | C28: NUMBER | D28: ไม่บังคับ | F28: 2000.00 | G28: ส่วนต่างที่ทำให้ 3 ทางไม่ผ่าน | H28: ระบบสร้าง/คำนวณ
A29: Purchase_Orders | B29: match_block | C29: TEXT | D29: ไม่บังคับ | F29: ยอดใบแจ้งหนี้เกิน PO | G29: เหตุผลที่ยังปิดไม่ได้ แสดงให้ AC เห็น | H29: ระบบสร้าง/คำนวณ
A30: Purchase_Orders | B30: from_quote_no | C30: TEXT | D30: ไม่บังคับ | E30: FK | F30: Quotations.quote_no | G30: ถ้าเปิดจากใบเสนอราคา เก็บเลขไว้ตามรอยกลับ | H30: ระบบสร้าง/คำนวณ
A31: Purchase_Orders | B31: drive_folder_id | C31: FILE_ID | D31: บังคับ | G31: โฟลเดอร์ของรายการนี้ในไดรฟ์กลาง MGS-Documents | H31: ระบบสร้าง/คำนวณ
A32: Purchase_Orders | B32: entry_type | C32: ENUM | D32: บังคับ | F32: PO / CASH | G32: PO = เปิด PO ใน B1 · CASH = ซื้อเงินสดไม่มี PO | H32: ระบบสร้าง/คำนวณ
A33: Purchase_Orders | B33: cash_reason | C33: TEXT | D33: ไม่บังคับ | F33: ร้านไม่รับเครดิต ต้องจ่ายสดหน้างาน | G33: บังคับเมื่อ entry_type = CASH — เหตุผลที่ไม่เปิด PO (กฎ C1) | H33: คนกรอก
A34: Purchase_Orders | B34: cash_paid_from | C34: ENUM | D34: ไม่บังคับ | F34: PETTY / OWN / TRANSFER | G34: จ่ายจากเงินสดย่อย / พนักงานสำรองจ่าย / โอนจากบัญชีบริษัท | H34: คนกรอก
A35: Purchase_Orders | B35: qc_bypassed | C35: BOOLEAN | D35: บังคับ | F35: TRUE / FALSE | G35: ล็อตนี้ข้ามการตรวจรับของ QC หรือไม่ | H35: คนกรอก
A36: Purchase_Orders | B36: qc_bypass_reason | C36: TEXT | D36: ไม่บังคับ | F36: ผักสดตรวจหน้างานแล้ว | G36: บังคับเมื่อ qc_bypassed = TRUE (กฎ C3) — แก้ย้อนหลังไม่ได้ | H36: คนกรอก
A37: Purchase_Orders | B37: qc_bypass_by | C37: TEXT | D37: ไม่บังคับ | E37: FK | F37: Users.email | G37: ใครเป็นผู้อนุมัติให้ข้าม QC | H37: ระบบสร้าง/คำนวณ
A38: Purchase_Orders | B38: qc_bypass_at | C38: DATETIME | D38: ไม่บังคับ | G38: เวลาที่กดยืนยันการข้าม QC | H38: ระบบสร้าง/คำนวณ
A39: Purchase_Orders | B39: bundle_doc_id | C39: UUID | D39: ไม่บังคับ | E39: FK | F39: Documents.doc_id | G39: ไฟล์รวมเล่ม — ว่างจนกว่าจะปิดรายการ | H39: ระบบสร้าง/คำนวณ
A40: Purchase_Orders | B40: bundle_at | C40: DATETIME | D40: ไม่บังคับ | G40: เวลาที่รวมเล่มเสร็จ | H40: ระบบสร้าง/คำนวณ
A41: Purchase_Orders | B41: created_by | C41: TEXT | D41: บังคับ | G41: ผู้สร้าง | H41: ระบบสร้าง/คำนวณ
...

Sheet ขั้นตอนงาน
A1: ขั้นตอนงาน (Stage_Templates) — module DOMESTIC_FOOD
A2: SLA แก้ได้ที่คอลัมน์เหลือง · เพิ่มงานนำเข้า/Solar ในอนาคต = เพิ่มแถว ไม่ต้องแก้โปรแกรม
A4: ลำดับ | B4: รหัสขั้น | C4: ชื่อขั้น (ที่ผู้ใช้เห็น) | D4: แผนกเจ้าของ | E4: เฟส | F4: SLA (ชม.) | G4: เงื่อนไขข้ามขั้น | H4: ถ้าไม่ผ่านไปไหน | I4: หมายเหตุของทีม
A5: 1 | B5: PRICE_REQUEST | C5: เช็คราคา | D5: SR | E5: BUY | F5: 24 | G5: เปิดจากใบเสนอราคา = ข้ามขั้นนี้ | I5: ผูกกับใบขอราคา/ใบเสนอราคาแล้ว
A6: 2 | B6: SAMPLE_CHECK | C6: ตรวจตัวอย่าง | D6: QC | E6: BUY | F6: 48 | G6: ดูตัวอย่างก่อนซื้อไม่ได้ | H6: REJECTED
A7: 3 | B7: GM_DECISION | C7: ผู้บริหารตัดสินใจ | D7: GM | E7: BUY | F7: 24 | G7: ตรวจตัวอย่างผ่านแล้ว | H7: CANCELLED
A8: 4 | B8: ORDER_CONFIRM | C8: คอนเฟิร์มออเดอร์ | D8: SR | E8: BUY | F8: 24
A9: 5 | B9: PI_RECEIVED | C9: รับ PI จากผู้ขาย | D9: SR | E9: BUY | F9: 48
A10: 6 | B10: ITEM_CODE | C10: เปิดรหัสสินค้า | D10: LS | E10: BUY | F10: 24 | G10: มีรหัสใน B1 แล้ว | I10: ข้ามไม่ได้จนกว่าจะมีรหัสจริงจาก B1
A11: 7 | B11: PO_CREATED | C11: ผูกกับ PO ใน B1 | D11: SR | E11: BUY | F11: 24 | I11: กดปุ่มดึงจาก B1 ไม่ให้พิมพ์เลขเอง
A12: 8 | B12: INTERNAL_APPROVAL | C12: อนุมัติภายใน | D12: GM | E12: BUY | F12: 24 | H12: ตีกลับหา SR
A13: 9 | B13: SUPPLIER_SIGN | C13: ผู้ขายเซ็น PO กลับ | D13: SR | E13: BUY | F13: 72 | I13: เก็บเฉพาะ PO ที่เซ็นครบแล้ว
A14: 10 | B14: DELIVERY_BOOKING | C14: จองรถรับของ | D14: LS | E14: RECV | F14: 24 | I14: จองล่วงหน้า 1 วัน
A15: 11 | B15: QC_INCOMING | C15: QC ตรวจรับ | D15: QC | E15: RECV | F15: 24 | H15: CLAIM | I15: ไม่ผ่าน = เปิดเคลม + ล็อกงวดจ่าย
A16: 12 | B16: GR | C16: รับเข้าคลัง + GRPO | D16: WH | E16: RECV | F16: 24 | I16: ดึงจาก OPDN/PDN1 ของ B1
A17: 13 | B17: INVOICE_RECEIVED | C17: รับใบแจ้งหนี้ | D17: AC | E17: AP | F17: 72 | I17: ยังต้องยืนยันว่า SR หรือ AC เป็นคนอัพ
A18: 14 | B18: DOC_HANDOVER | C18: ส่งมอบเอกสาร | D18: SR | E18: AP | F18: 24
A19: 15 | B19: PAYMENT | C19: ทำจ่าย | D19: AC | E19: PAY | F19: 48 | I19: ตั้งเรื่อง → อนุมัติ → บันทึกจ่าย
A20: 16 | B20: RECEIPT_ORIGINAL | C20: ใบเสร็จตัวจริง | D20: AC | E20: PAY | F20: 336 | I20: 336 ชม. = 14 วัน · รอยืนยันว่าส่งตรงถึง AC ได้ไหม
A21: 17 | B21: AC_CLOSE | C21: ตรวจ 3 ทาง + ปิด | D21: AC | E21: PAY | F21: 48
B23: รวม SLA ทั้งกระบวนการ (ชม.) | F23: =SUM(F5:F21)
B24: คิดเป็นวันทำการ (8 ชม./วัน) | F24: =ROUND(F23/8,1)
B26: SLA ที่ใส่ไว้เป็นค่าที่ผมตั้งเอง — ต้องให้หัวหน้าแต่ละแผนกยืนยันว่าทำได้จริง ก่อนเปิดใช้ระบบเตือน มิฉะนั้นระบบจะเตือนตลอดเวลาจนคนปิดการแจ้งเตือน

Sheet เอกสารที่ต้องมี
A1: เอกสารที่ต้องมี (Doc_Templates)
A2: เอกสารบังคับต่อ PO หนึ่งใบ · สลิปไม่อยู่ในรายการนี้เพราะผูกกับ «งวดจ่าย» ไม่ใช่ผูกกับ PO
A4: รหัสเอกสาร | B4: ชื่อเอกสาร | C4: เจ้าของ | D4: เกิดที่ขั้น | E4: บังคับ | F4: ต้องกรอกยอด | G4: เก็บที่โฟลเดอร์ | H4: หมายเหตุของทีม
A5: PI | B5: PI จากผู้ขาย | C5: SR | D5: PI_RECEIVED | E5: บังคับ | F5: TRUE | G5: 01_PO/.../01_PI/
A6: PO_SIGNED | B6: PO ที่เซ็นครบแล้ว | C6: SR | D6: SUPPLIER_SIGN | E6: บังคับ | F6: TRUE | G6: 01_PO/.../02_PO/ | H6: เก็บเฉพาะใบที่เซ็นครบ — PO ที่ยังไม่เซ็นอยู่ใน B1 แล้ว
A7: PATTERN_LABEL | B7: Pattern label | C7: SR | D7: SUPPLIER_SIGN | E7: ไม่บังคับ | F7: FALSE | G7: 01_PO/.../02_PO/ | H7: ยังต้องยืนยันว่าใช้กับสินค้ากลุ่มไหน
A8: QC_RC | B8: ผลตรวจรับ / RC + รูป | C8: QC | D8: QC_INCOMING | E8: บังคับ | F8: TRUE | G8: 01_PO/.../03_QC/ | H8: จำนวนที่ QC รับ คือตัวเลขที่ใช้ตรวจ 3 ทาง ไม่ใช่จำนวนที่ส่งมา
A9: GR | B9: ใบรับสินค้า (GRPO) | C9: WH | D9: GR | E9: บังคับ | F9: TRUE | G9: 01_PO/.../04_GR/ | H9: ดึงจาก B1 (OPDN/PDN1)
A10: INVOICE | B10: ใบแจ้งหนี้ | C10: AC | D10: INVOICE_RECEIVED | E10: บังคับ | F10: TRUE | G10: 01_PO/.../05_Invoice/ | H10: เลขที่ใบแจ้งหนี้ดึงจาก OPCH.NumAtCard ของ B1
A11: CREDIT_NOTE | B11: ใบลดหนี้ | C11: AC | D11: (เมื่อมีเคลม) | E11: ตามเงื่อนไข | F11: TRUE | G11: 01_PO/.../05_Invoice/ | H11: ตัวปลดล็อกงวดจ่ายที่ถูกล็อกจากเคลม
A12: SLIP | B12: สลิป / Swift | C12: AC | D12: PAYMENT | E12: บังคับทุกงวด | F12: TRUE | G12: 01_PO/.../06_Payment/ | H12: ผูกกับงวดจ่าย ไม่ใช่กับ PO — 2 งวดก็มี 2 สลิป
A13: RECEIPT | B13: ใบเสร็จตัวจริง | C13: AC | D13: RECEIPT_ORIGINAL | E13: บังคับ | F13: TRUE | G13: 01_PO/.../06_Payment/
A15: จำนวนเอกสารบังคับต่อ PO | B15: =COUNTIF(E5:E13,"บังคับ")

Sheet กฎตรวจสอบ
A1: กฎตรวจสอบก่อนบันทึก
A2: กฎที่ระบบใช้บล็อกหรือเตือน · «เกณฑ์» และ «ระดับ» แก้ได้ — ตัวเลขที่เป็นสีแดงคือค่าที่ผมตั้งเองและต้องให้ทีมยืนยัน
A4: รหัส | B4: จังหวะ | C4: กฎ | D4: ระดับ | E4: เกณฑ์ (แก้ได้) | F4: ข้อความที่ผู้ใช้เห็น | G4: สถานะ | H4: หมายเหตุของทีม
A5: V1 | B5: ขณะพิมพ์ | C5: จำนวน / มูลค่า ต้องมากกว่า 0 | D5: บล็อก | E5: > 0 | F5: จำนวนต้องมากกว่า 0 | G5: ใช้งาน
A6: V2 | B6: ขณะพิมพ์ | C6: วันครบกำหนดจ่าย ต้องไม่ก่อนวันเปิด PO | D6: บล็อก | E6: ≥ วันเปิด PO | F6: วันครบกำหนดอยู่ก่อนวันเปิด PO | G6: ใช้งาน
A7: V3 | B7: ขณะพิมพ์ | C7: อีเมล / เบอร์ผู้ขาย รูปแบบถูกต้อง | D7: เตือน | E7: รูปแบบมาตรฐาน | F7: ขีดเส้นใต้แดงใต้ช่อง | G7: ใช้งาน
A8: V4 | B8: ตอนบันทึก | C8: ไฟล์แนบครบตามที่ขั้นนั้นบังคับ | D8: บล็อก | E8: ครบทุกใบที่ is_required | F8: ยังขาด: ใบแจ้งหนี้ | G8: ใช้งาน
A9: V5 | B9: ตอนบันทึก | C9: ชนิดและขนาดไฟล์ | D9: บล็อก | E9: pdf/jpg/png · ≤ 20 MB | F9: รองรับ PDF/JPG/PNG ไม่เกิน 20 MB | G9: ใช้งาน
A10: V6 | B10: ตอนบันทึก | C10: ไฟล์ซ้ำ (checksum ตรงกับที่มีแล้ว) | D10: เตือน | E10: MD5 ตรงกัน | F10: ไฟล์นี้อัพไปแล้วเมื่อ 2 ส.ค. — ต้องการทับหรือไม่ | G10: ใช้งาน
A11: V7 | B11: ตอนบันทึก | C11: ผลรวมงวดจ่าย = มูลค่า PO | D11: บล็อก | E11: ต่างได้ไม่เกิน 1 บาท | F11: งวดจ่ายรวมไม่เท่ากับมูลค่า PO | G11: ใช้งาน
A12: V8 | B12: ตอนบันทึก | C12: จำนวนใน GR ต้องไม่เกินจำนวนใน PO | D12: บล็อก | E12: GR ≤ PO | F12: GR 520 KG เกิน PO 500 KG | G12: ใช้งาน
A13: V9 | B13: ตอนบันทึก | C13: ยอดใบแจ้งหนี้ต่างจาก PO (ระดับเตือน) | D13: เตือน | E13: > 2% | F13: ยอดต่างจาก PO 1.5% — ระบุเหตุผล | G13: รอทีมยืนยันเกณฑ์ | H13: AC ต้องยืนยัน 2% ว่าเหมาะสม
A14: V10 | B14: ตอนบันทึก | C14: ยอดใบแจ้งหนี้ต่างจาก PO (ระดับบล็อก) | D14: บล็อก | E14: > 5% | F14: ต่างเกิน 5% ต้องให้จัดซื้อแก้ที่ต้นทางก่อน | G14: รอทีมยืนยันเกณฑ์ | H14: AC ต้องยืนยัน 5% ว่าเหมาะสม
A15: V11 | B15: ตอนบันทึก | C15: วันที่ในเอกสารต้องไม่อยู่ในอนาคต | D15: เตือน | E15: ≤ วันนี้ | F15: วันที่ในใบแจ้งหนี้เป็นวันข้างหน้า | G15: ใช้งาน
A16: V12 | B16: ตอนบันทึก | C16: เลขที่ใบแจ้งหนี้ไม่ซ้ำต่อผู้ขายเดียวกัน | D16: บล็อก | E16: ไม่ซ้ำ | F16: เลขใบแจ้งหนี้นี้ใช้แล้วใน PO-26-0031 | G16: ใช้งาน | H16: เทียบกับ OPCH.NumAtCard ของ B1 ด้วย
A17: V13 | B17: เปลี่ยนขั้น | C17: เอกสารบังคับของขั้นก่อนหน้าครบทุกใบ | D17: บล็อก | E17: ครบ 100% | F17: ยังขาดเอกสารจากขั้นก่อน | G17: ใช้งาน
A18: V14 | B18: เปลี่ยนขั้น | C18: ไม่มีใบเคลมที่ยังไม่ได้ใบลดหนี้ | D18: บล็อก | E18: ไม่มีเคลมค้าง | F18: มีใบเคลมที่ยังไม่ได้รับใบลดหนี้ | G18: ใช้งาน
A19: V15 | B19: เปลี่ยนขั้น | C19: ทุกงวดจ่ายเป็น PAID และมีสลิปครบ | D19: บล็อก | E19: ทุกงวด | F19: ยังจ่ายไม่ครบ | G19: ใช้งาน
A20: V16 | B20: เปลี่ยนขั้น | C20: ตรวจ 3 ทางผ่าน — เทียบกับจำนวนที่ QC รับ | D20: บล็อก | E20: PO x QC รับ x ใบแจ้งหนี้ | F20: ตรวจ 3 ทางยังไม่ผ่าน | G20: ใช้งาน | H20: สำคัญ: เทียบกับจำนวนที่ QC รับ ไม่ใช่จำนวนที่ส่งมา
A21: V17 | B21: เปลี่ยนขั้น | C21: ผู้อนุมัติต้องไม่ใช่ผู้สร้าง/ผู้อัพโหลด | D21: บล็อก | E21: คนละคน | F21: อนุมัติเอกสารของตัวเองไม่ได้ | G21: ใช้งาน
A22: V18 | B22: เปลี่ยนขั้น | C22: ต้องมีรหัสสินค้าจริงจาก B1 แล้ว | D22: บล็อก | E22: sap_item_code ไม่ว่าง | F22: ยังไม่มีรหัสสินค้าจาก B1 | G22: ใช้งาน
A23: P1 | B23: ขณะพิมพ์ | C23: วันที่จ่ายต้องไม่เป็นวันในอนาคต | D23: บล็อก | E23: ≤ วันนี้ | F23: วันที่จ่ายเป็นวันข้างหน้า — บันทึกได้เมื่อจ่ายจริงแล้ว | G23: ใช้งาน
A24: P2 | B24: ขณะพิมพ์ | C24: วันที่ธนาคารตัดเงิน ≥ วันที่จ่าย | D24: บล็อก | E24: ≥ payment_date | F24: วันที่ธนาคารตัดเงินต้องไม่ก่อนวันที่จ่าย | G24: ใช้งาน
A25: P3 | B25: ขณะพิมพ์ | C25: จำนวนเงินที่จ่ายต้องมากกว่า 0 | D25: บล็อก | E25: > 0 | F25: จำนวนเงินต้องมากกว่า 0 | G25: ใช้งาน
A26: P4 | B26: ขณะพิมพ์ | C26: อัตราภาษีหัก ณ ที่จ่ายอยู่ในช่วงปกติ | D26: บล็อก | E26: 0–15% | F26: อัตราหัก ณ ที่จ่ายผิดปกติ | G26: รอทีมยืนยันเกณฑ์ | H26: รออัตราจริงที่บริษัทใช้
A27: P5 | B27: ตอนบันทึก | C27: ต้องแนบสลิป / Swift | D27: บล็อก | E27: บังคับ | F27: ต้องแนบสลิปหรือ Swift ก่อนบันทึกการจ่าย | G27: ใช้งาน
A28: P6 | B28: ตอนบันทึก | C28: ต้องมีเลขอ้างอิงธนาคาร | D28: บล็อก | E28: บังคับ | F28: ต้องใส่เลขอ้างอิงเพื่อกระทบยอดกับ statement | G28: ใช้งาน
A29: P7 | B29: ตอนบันทึก | C29: ยอดที่จ่ายต่างจากที่คำนวณ | D29: เตือน | E29: > 1 บาท | F29: ยอดต่างจากที่คำนวณ — ระบุเหตุผล | G29: ใช้งาน | H29: เหตุผลขึ้นในรายงานของหัวหน้าบัญชี
A30: P8 | B30: ตอนบันทึก | C30: ยอดสะสมที่จ่ายต้องไม่เกินมูลค่า PO | D30: บล็อก | E30: ≤ มูลค่า PO | F30: จ่ายรวมเกินมูลค่า PO | G30: ใช้งาน
A31: P9 | B31: ตอนบันทึก | C31: จ่ายย้อนหลังเกินกำหนด | D31: เตือน | E31: > 7 วัน | F31: จ่ายย้อนหลัง X วัน — ต้องขออนุมัติเพิ่ม | G31: รอทีมยืนยันเกณฑ์ | H31: AC ต้องยืนยันว่า 7 วันเหมาะสม
A32: P10 | B32: ตอนบันทึก | C32: งวดบัญชีต้องยังไม่ปิด | D32: บล็อก | E32: posting_period ยังเปิด | F32: งวดบัญชีปิดแล้ว — บันทึกในงวดปัจจุบันแทน | G32: ใช้งาน
A33: P11 | B33: ตอนบันทึก | C33: เลขอ้างอิงธนาคารห้ามซ้ำ | D33: บล็อก | E33: ไม่ซ้ำทั้งระบบ | F33: เลขอ้างอิงนี้ใช้แล้วใน PO-26-0031 งวด 1 | G33: ใช้งาน | H33: กฎที่ป้องกันการจ่ายซ้ำ — ความผิดพลาดที่แพงที่สุดในงาน AP
A34: P12 | B34: ตอนบันทึก | C34: งวดต้องอยู่ในสถานะ APPROVED | D34: บล็อก | E34: =APPROVED | F34: งวดนี้ยังไม่ผ่านการอนุมัติจ่าย | G34: ใช้งาน
A35: C1 | B35: ตอนบันทึก | C35: ซื้อเงินสดต้องระบุเหตุผลที่ไม่เปิด PO | D35: บล็อก | E35: ต้องมีข้อความ | F35: ต้องบอกเหตุผลที่ไม่เปิด PO — ผู้ตรวจสอบบัญชีถามทุกครั้ง | G35: ใช้งาน | H35: ช่องนี้คือสิ่งเดียวที่ทำให้การซื้อเงินสดตรวจสอบได้
A36: C2 | B36: ตอนบันทึก | C36: วันที่จ่ายเงินสดต้องไม่เป็นวันข้างหน้า | D36: บล็อก | E36: ≤ วันนี้ | F36: วันที่จ่ายเป็นวันข้างหน้า — บันทึกได้เมื่อจ่ายจริงแล้ว | G36: ใช้งาน
A37: C3 | B37: ตอนบันทึก | C37: ข้าม QC ต้องระบุเหตุผลและผู้อนุมัติ | D37: บล็อก | E37: ต้องมีทั้ง 2 ช่อง | F37: ข้าม QC ต้องระบุเหตุผลและชื่อผู้อนุมัติ — เก็บเป็นหลักฐานถาวร | G37: ใช้งาน | H37: หัวหน้า QC เห็นทุกใบที่ข้ามในทะเบียนรายการเงินสด
A38: C4 | B38: ตอนบันทึก | C38: ยอดซื้อเงินสดต่อรายการต้องไม่เกินเพดาน | D38: บล็อก | E38: ≤ 50,000 บาท | F38: เงินสดเกิน 50,000 บาท ต้องเปิด PO | G38: รอทีมยืนยันเกณฑ์ | H38: ผู้บริหาร + บัญชี ต้องยืนยันเพดานนี้ · ตั้งไว้เท่าวงเงินอนุมัติจ่าย
A39: C5 | B39: ขณะพิมพ์ | C39: ร้าน / สินค้า / จำนวน / ยอดเงิน ต้องไม่ว่าง | D39: บล็อก | E39: ครบทั้ง 4 ช่อง | F39: ยังกรอกไม่ครบ | G39: ใช้งาน
A40: U1 | B40: ตอนบันทึก | C40: ขั้นที่มีเอกสารบังคับ ต้องแนบไฟล์ก่อนส่งต่อ | D40: บล็อก | E40: ครบตาม Doc_Templates | F40: ขั้นนี้ต้องแนบใบรับสินค้า (GRPO) ก่อนถึงจะส่งต่อได้ | G40: ใช้งาน | H40: แทนพฤติกรรมเดิมที่กดปุ่มเสร็จแล้วส่งต่อทันทีโดยไม่มีหลักฐาน
A41: U2 | B41: ตอนบันทึก | C41: ขั้นที่ไม่แนบไฟล์ ต้องเขียนหมายเหตุแทน | D41: บล็อก | E41: ติ๊กไม่มีเอกสาร + มีหมายเหตุ | F41: ไม่แนบไฟล์ต้องเขียนหมายเหตุว่าทำอะไรไปในขั้นนี้ | G41: ใช้งาน
...

Sheet สิทธิ์แต่ละแผนก
A1: สิทธิ์แต่ละแผนก
A2: C=สร้าง · R=ดู · U=แก้ · A=อนุมัติ · — =ไม่มีสิทธิ์ · แก้ได้ทั้งตาราง ถ้าเห็นว่าไม่ตรงกับงานจริง
A4: หน้าที่ | B4: SR | C4: SR Head | D4: QC | E4: QC Head | F4: LS | G4: WH | H4: AC | I4: AC Head | J4: GM | K4: หมายเหตุของทีม
A5: สร้าง/แก้ PO | B5: C R U | C5: R U | D5: R | E5: R | F5: R | G5: R | H5: R | I5: R | J5: R
A6: ยอดเงิน / ราคา | B6: R U | C6: R U | D6: — | E6: — | F6: — | G6: — | H6: R U | I6: R U | J6: R | K6: QC/LS/WH ไม่เห็นช่องราคาเลย ไม่ใช่แค่แก้ไม่ได้
A7: ใบขอราคา / ใบเสนอราคา | B7: C R U | C7: R U | D7: — | E7: — | F7: — | G7: — | H7: R | I7: R | J7: R | K7: เพิ่มใหม่ล่าสุด
A8: อัพโหลด PI / PO | B8: C U | C8: C U | D8: — | E8: — | F8: — | G8: — | H8: R | I8: R | J8: R
A9: อนุมัติ PO | B9: — | C9: A | D9: — | E9: — | F9: — | G9: — | H9: — | I9: — | J9: A
A10: ผลตรวจ QC | B10: R | C10: R | D10: C U | E10: C U A | F10: R | G10: R | H10: R | I10: R | J10: R
A11: เปิดรหัสสินค้า | B11: C (ขอ) | C11: A | D11: — | E11: — | F11: U | G11: — | H11: — | I11: — | J11: — | K11: LS เป็นคนบันทึกรหัสจาก B1 กลับ
A12: จองรถ | B12: R | C12: R | D12: R | E12: R | F12: C U | G12: R | H12: — | I12: — | J12: R
A13: GRPO | B13: R | C13: R | D13: R | E13: R | F13: R | G13: C U | H13: R | I13: R | J13: R
A14: ใบแจ้งหนี้ | B14: R | C14: R | D14: — | E14: — | F14: — | G14: — | H14: C U | I14: R | J14: R | K14: รอยืนยันว่า SR หรือ AC เป็นคนอัพ
A15: ตั้งเรื่องขอจ่าย | B15: — | C15: — | D15: — | E15: — | F15: — | G15: — | H15: C | I15: R | J15: R
A16: อนุมัติจ่าย | B16: — | C16: — | D16: — | E16: — | F16: — | G16: — | H16: — | I16: A | J16: A | K16: เกินวงเงินต้องถึงผู้บริหาร
A17: บันทึกการจ่าย + สลิป | B17: R | C17: R | D17: — | E17: — | F17: — | G17: — | H17: C U | I17: R U | J17: R | K17: ต้องคนละคนกับผู้อนุมัติ
A18: กลับรายการจ่าย | B18: — | C18: — | D18: — | E18: — | F18: — | G18: — | H18: — | I18: A | J18: R | K18: หัวหน้าบัญชีเท่านั้น
A19: เคลม | B19: R U | C19: A | D19: C U | E19: A | F19: — | G19: R | H19: R | I19: R | J19: R
A20: ปลดล็อกเคลม | B20: — | C20: — | D20: — | E20: A | F20: — | G20: — | H20: — | I20: — | J20: — | K20: QC ที่ตรวจ ปลดล็อกของตัวเองไม่ได้
A21: ตรวจ 3 ทาง / ปิด PO | B21: R | C21: R | D21: — | E21: — | F21: — | G21: — | H21: C U | I21: A | J21: R
A22: ดูรายงานทั้งบริษัท | B22: — | C22: R | D22: — | E22: R | F22: — | G22: — | H22: R | I22: R | J22: R
A23: แจ้งปัญหา (bug) | B23: C | C23: C | D23: C | E23: C | F23: C | G23: C | H23: C | I23: C | J23: C | K23: ทุกคนแจ้งได้จากทุกหน้า
A24: ตั้งค่าระบบ / ผู้ใช้ | B24: — | C24: — | D24: — | E24: — | F24: — | G24: — | H24: — | I24: — | J24: — | K24: IT/แอดมินเท่านั้น และไม่อยู่ในสายอนุมัติ
A26: กฎแยกหน้าที่ที่บังคับด้วยโปรแกรม ไม่ใช่ด้วยความไว้ใจ: ผู้สร้างอนุมัติงานตัวเองไม่ได้ · ผู้ตั้งเรื่องขอจ่าย ≠ ผู้อนุมัติ ≠ ผู้บันทึกจ่าย · QC ที่ตรวจ ปลดล็อกเคลมของตัวเองไม่ได้ · แอดมินระบบไม่อยู่ในสายอนุมัติ

Sheet การแจ้งเตือน
A1: การแจ้งเตือน
A2: ภายในใช้ Lark อย่างเดียว (ตัดสินใจแล้ว) · ชั้น 1 ในเว็บทุกเรื่อง · ชั้น 2 Lark เฉพาะที่ต้องลงมือ · ชั้น 3 อีเมลสรุป
A4: เหตุการณ์ | B4: ใครได้รับ | C4: ช่องทาง | D4: เมื่อไหร่ | E4: เปิดใช้ | F4: หมายเหตุของทีม
A5: งานเข้าคิวของคุณ | B5: เจ้าของขั้นถัดไป | C5: 1 + 2 | D5: ทันที | E5: TRUE | F5: ปิดไม่ได้ — กันคนอ้างว่าไม่รู้
A6: เอกสารที่คุณต้องอัพยังไม่มา | B6: เจ้าของเอกสาร | C6: 1 + 2 | D6: ทุกเช้า 08:30 | E6: TRUE
A7: ค้างเกิน SLA 100% | B7: ผู้ถืองาน | C7: 1 + 2 | D7: วันละครั้ง | E7: TRUE
A8: ค้างเกิน SLA 150% | B8: ผู้ถืองาน + หัวหน้าแผนก | C8: 1 + 2 + 3 | D8: วันละครั้ง | E8: TRUE
A9: ค้างเกิน SLA 200% | B9: + ผู้บริหาร (ในสรุปรายวัน) | C9: 3 อีเมล | D9: 08:30 | E9: TRUE
A10: รออนุมัติ | B10: ผู้อนุมัติตามวงเงิน | C10: 1 + 2 | D10: ทันที | E10: TRUE
A11: ตรวจรับไม่ผ่าน / เปิดเคลม | B11: SR + AC + หัวหน้า QC | C11: 1 + 2 | D11: ทันที | E11: TRUE | F11: แจ้งพร้อมกัน 3 แผนก
A12: ได้รับใบลดหนี้ → ปลดล็อกจ่าย | B12: AC | C12: 1 + 2 | D12: ทันที | E12: TRUE
A13: งวดจ่ายครบกำหนดใน 3 วัน | B13: AC | C13: 1 + 3 | D13: 08:30 | E13: TRUE
A14: งวดเลยกำหนดแล้วยังไม่จ่าย | B14: AC + หัวหน้าบัญชี | C14: 1 + 2 + 3 | D14: ทุกวัน 08:30 | E14: TRUE
A15: ตั้งเรื่องขอจ่าย | B15: ผู้อนุมัติตามวงเงิน | C15: 1 + 2 | D15: ทันที | E15: TRUE
A16: อนุมัติ / ตีกลับคำขอจ่าย | B16: ผู้ตั้งเรื่อง | C16: 1 + 2 | D16: ทันที | E16: TRUE
A17: บันทึกจ่ายแล้ว | B17: SR ผู้ดูแล PO | C17: 1 + 2 | D17: ทันที | E17: TRUE
A18: บันทึกจ่ายแล้ว — แจ้งผู้ขาย | B18: ผู้ขาย (อีเมล + สลิป) | C18: 3 อีเมล | D18: ทันที | E18: TRUE | F18: ตัดขั้นที่ AC ส่งสลิปให้ SR แล้ว SR ส่งต่อ
A19: ธนาคารตีกลับ | B19: AC + หัวหน้าบัญชี | C19: 1 + 2 | D19: ทันที | E19: TRUE
A20: จ่ายครบทุกงวด | B20: SR + AC | C20: 1 + 2 | D20: ทันที | E20: TRUE
A21: ใบเสร็จตัวจริงยังไม่มาเกิน 15 วัน | B21: AC | C21: 1 + 2 | D21: ทุก 7 วัน | E21: TRUE
A22: การตรวจสอบไม่ผ่าน (ยอดไม่ตรง) | B22: ผู้กด + แผนกที่ต้องแก้ | C22: 1 + 2 | D22: ทันที | E22: TRUE
A23: PO ปิดแล้ว | B23: ทุกคนที่เคยแตะ PO นี้ | C23: 1 ในเว็บ | D23: ทันที | E23: TRUE
A24: สรุปงานค้างของฉัน | B24: ทุกคน | C24: 3 อีเมล | D24: 08:30 จ–ศ | E24: TRUE | F24: ไม่มีงานค้าง = ไม่ส่ง
A25: แจ้งบั๊กระดับ «ทำงานต่อไม่ได้» | B25: กลุ่ม Lark ของ IT | C25: 2 Lark | D25: ทันที | E25: TRUE
A26: Lark ส่งไม่สำเร็จครบ 5 ครั้ง | B26: ผู้รับเดิม (ผ่านอีเมลแทน) | C26: 3 อีเมล | D26: อัตโนมัติ | E26: TRUE | F26: จำเป็นเพราะไม่มีช่องทางที่สองแล้ว
A27: Lark ล้มเหลว > 10 ข้อความใน 15 นาที | B27: แอดมินระบบ + แบนเนอร์ในเว็บ | C27: 1 + 3 | D27: ทันที | E27: TRUE
A28: ดึงข้อมูลจาก B1 ล้มเหลว | B28: แอดมินระบบ | C28: 1 + 2 | D28: ทันที | E28: TRUE
A30: กติกากันสแปม (สำคัญกว่าตัวระบบแจ้งเตือนเอง)
A31: • ไม่แจ้งการกระทำของตัวเอง — ตัดข้อความไปได้ประมาณ 40%
A32: • เรื่องเดิมไม่เด้งซ้ำใน 24 ชม. (dedupe_key = เหตุการณ์ + เอกสาร + ผู้รับ + วัน)
A33: • เกิน 3 เรื่องใน 10 นาที รวมเป็นข้อความเดียว
A34: • เงียบ 20:00–07:00 และวันหยุด ยกเว้นเรื่องด่วน
A35: • ผู้ใช้ปิดรายประเภทได้เอง ยกเว้น «งานเข้าคิวของคุณ» ที่ปิดไม่ได้

Sheet สถานะ
A1: สถานะทั้งหมดของแต่ละเอกสาร
A2: สถานะไหนเปลี่ยนไปไหนได้บ้าง และใครเป็นคนทำให้เปลี่ยน
A4: เอกสาร | B4: สถานะ | C4: หมายความว่า | D4: เปลี่ยนไปสถานะไหนได้ | E4: ใครทำให้เปลี่ยน | F4: หมายเหตุของทีม
A5: Purchase_Orders | B5: ACTIVE | C5: กำลังดำเนินการ | D5: COMPLETED / CANCELLED | E5: ระบบ / SR
B6: COMPLETED | C6: ปิดบัญชีแล้ว | D6: (สิ้นสุด) | E6: AC | F6: ปิดได้เมื่อผ่านกฎ V13–V18 ครบ
B7: CANCELLED | C7: ยกเลิก | D7: (สิ้นสุด) | E7: SR + หัวหน้า
A8: PO_Payments | B8: PENDING | C8: รอตั้งเรื่องขอจ่าย | D8: REQUESTED / BLOCKED / CANCELLED | E8: ระบบ
B9: BLOCKED | C9: ล็อกเพราะมีเคลมค้าง | D9: PENDING | E9: ระบบ (เมื่อได้ใบลดหนี้)
B10: REQUESTED | C10: ตั้งเรื่องแล้ว รออนุมัติ | D10: APPROVED / PENDING | E10: AC ตั้ง · ผู้อนุมัติตัดสิน
B11: APPROVED | C11: อนุมัติแล้ว รอทำจ่าย | D11: PAID / PENDING | E11: หัวหน้าบัญชี / ผู้บริหาร
B12: PAID | C12: จ่ายแล้ว มีสลิป | D12: FAILED / VOID | E12: AC (คนละคนกับผู้อนุมัติ)
B13: FAILED | C13: ธนาคารตีกลับ | D13: APPROVED | E13: AC
B14: VOID | C14: กลับรายการเพราะจ่ายผิด | D14: (สิ้นสุด — เปิดงวดใหม่แทน) | E14: หัวหน้าบัญชี | F14: ไม่มีการลบ ของเดิมอยู่เป็นหลักฐาน
B15: CANCELLED | C15: ยกเลิกงวด | D15: (สิ้นสุด) | E15: หัวหน้าบัญชี
A16: Claims | B16: OPEN | C16: เปิดเรื่องแล้ว | D16: SENT_TO_SUPPLIER | E16: QC / Sales Coordinator
B17: SENT_TO_SUPPLIER | C17: ส่งเคลมให้ผู้ขายแล้ว | D17: CN_RECEIVED | E17: SR
B18: CN_RECEIVED | C18: ได้รับใบลดหนี้ | D18: CLOSED | E18: AC | F18: ตัวปลดล็อกงวดจ่าย
B19: CLOSED | C19: ปิดเรื่อง | D19: (สิ้นสุด) | E19: หัวหน้า QC
A20: ItemCode_Requests | B20: DRAFT | C20: ร่าง | D20: WAIT_APPROVE | E20: SR
B21: WAIT_APPROVE | C21: รอหัวหน้าอนุมัติ | D21: WAIT_LS / REJECTED | E21: หัวหน้า SR
B22: WAIT_LS | C22: รอ LS เปิดรหัสใน B1 | D22: DONE | E22: LS
B23: DONE | C23: เปิดรหัสแล้ว | D23: (สิ้นสุด) | E23: LS | F23: PO ที่รออยู่เดินต่อเองอัตโนมัติ
B24: REJECTED | C24: ไม่อนุมัติ | D24: (สิ้นสุด) | E24: หัวหน้า SR
A25: Price_Requests | B25: NEW | C25: ยังไม่มีใบเสนอราคา | D25: QUOTING / CANCELLED | E25: SR | F25: เพิ่มใหม่ล่าสุด
B26: QUOTING | C26: กำลังเทียบราคา | D26: CONVERTED / CANCELLED | E26: SR | F26: เพิ่มใหม่ล่าสุด
B27: CONVERTED | C27: เปิด PO แล้ว | D27: (สิ้นสุด) | E27: SR | F27: เพิ่มใหม่ล่าสุด · เพิ่มใบเสนอราคาใหม่ไม่ได้แล้ว
B28: CANCELLED | C28: ยกเลิก | D28: (สิ้นสุด) | E28: SR | F28: เพิ่มใหม่ล่าสุด
A29: Payment_Requests | B29: PENDING | C29: รอหัวหน้าอนุมัติ | D29: APPROVED / REJECTED | E29: หัวหน้าบัญชี หรือผู้บริหารตามวงเงิน | F29: เพิ่มใหม่ล่าสุด
B30: APPROVED | C30: อนุมัติแล้ว รอบัญชีทำจ่าย | D30: (สิ้นสุด) | E30: หัวหน้าบัญชี / ผู้บริหาร | F30: เพิ่มใหม่ล่าสุด · งวดจ่ายเปลี่ยนเป็น APPROVED ตาม
B31: REJECTED | C31: ตีกลับพร้อมเหตุผล | D31: (สิ้นสุด — ขอใหม่เป็นคำขอใบใหม่) | E31: หัวหน้าบัญชี / ผู้บริหาร | F31: เพิ่มใหม่ล่าสุด · ของเดิมไม่ถูกลบ
A32: Issues | B32: NEW | C32: รอ IT รับเรื่อง | D32: ACK | E32: IT (SLA 1 วันทำการ)
B33: ACK | C33: รับเรื่องแล้ว | D33: FIXING / WONTFIX | E33: IT
B34: FIXING | C34: กำลังแก้ | D34: FIXED | E34: IT
B35: FIXED | C35: แก้แล้ว รอผู้แจ้งยืนยัน | D35: CLOSED / FIXING | E35: IT แก้ · ผู้แจ้งยืนยัน | F35: ผู้แจ้งเป็นคนกดปิด ไม่ใช่ IT
B36: CLOSED | C36: ปิดเรื่อง | D36: (สิ้นสุด) | E36: ผู้แจ้ง | F36: ไม่มีปุ่มลบ

Sheet ค่าตั้งต้น
A1: ค่าตั้งต้นทั้งหมด (Config)
A2: ตัวเลขที่ปรับได้ทั้งระบบอยู่ในแท็บเดียว · แถวสีแดงคือค่าที่ผมตั้งเองและยังไม่มีใครยืนยัน
A4: รหัสค่า | B4: หมวด | C4: ค่า (แก้ได้) | D4: ใช้ทำอะไร | E4: ใครยืนยัน | F4: หมายเหตุของทีม
A5: SLA_DEFAULT_HOURS | B5: ขั้นตอนงาน | C5: 24 | D5: SLA ตั้งต้นของขั้นที่ไม่ได้กำหนดเอง | E5: หัวหน้าทุกแผนก
A6: SLA_ESCALATE_1_PCT | B6: ขั้นตอนงาน | C6: 150 | D6: เกิน SLA กี่ % จึงแจ้งหัวหน้า | E6: หัวหน้าทุกแผนก
A7: SLA_ESCALATE_2_PCT | B7: ขั้นตอนงาน | C7: 200 | D7: เกิน SLA กี่ % จึงเข้าสรุปของผู้บริหาร | E7: ผู้บริหาร
A8: INVOICE_TOLERANCE_WARN_PCT | B8: ตรวจสอบ | C8: 2 | D8: ยอดใบแจ้งหนี้ต่างจาก PO กี่ % จึงเตือน | E8: AC | F8: กฎ V9
A9: INVOICE_TOLERANCE_BLOCK_PCT | B9: ตรวจสอบ | C9: 5 | D9: ต่างกี่ % จึงบล็อก | E9: AC | F9: กฎ V10
A10: PAYMENT_VARIANCE_TOLERANCE_THB | B10: จ่ายเงิน | C10: 1 | D10: ยอดจ่ายต่างจากที่คำนวณกี่บาทจึงต้องใส่เหตุผล | E10: AC | F10: กฎ P7
A11: PAYMENT_BACKDATE_DAYS | B11: จ่ายเงิน | C11: 7 | D11: จ่ายย้อนหลังได้กี่วันโดยไม่ต้องขออนุมัติเพิ่ม | E11: AC | F11: กฎ P9
A12: APPROVAL_LIMIT_AC_HEAD_THB | B12: จ่ายเงิน | C12: 50000 | D12: วงเงินที่หัวหน้าบัญชีอนุมัติได้เอง | E12: AC + ผู้บริหาร | F12: เกินนี้ต้องถึงผู้บริหาร
A13: SWIFT_ALWAYS_GM | B13: จ่ายเงิน | C13: TRUE | D13: จ่ายต่างประเทศต้องถึงผู้บริหารทุกวงเงิน | E13: AC + ผู้บริหาร
A14: WHT_RATE_GOODS | B14: ภาษี | C14: 0 | D14: อัตราหัก ณ ที่จ่าย — ซื้อสินค้า (%) | E14: AC
A15: WHT_RATE_FREIGHT | B15: ภาษี | C15: 1 | D15: อัตราหัก ณ ที่จ่าย — ค่าขนส่ง (%) | E15: AC
A16: WHT_RATE_SERVICE | B16: ภาษี | C16: 3 | D16: อัตราหัก ณ ที่จ่าย — ค่าบริการ (%) | E16: AC
A17: WHT_RATE_RENT | B17: ภาษี | C17: 5 | D17: อัตราหัก ณ ที่จ่าย — ค่าเช่า (%) | E17: AC
A18: WHT_RATE_ADS | B18: ภาษี | C18: 2 | D18: อัตราหัก ณ ที่จ่าย — ค่าโฆษณา (%) | E18: AC
A19: BANK_FEE_DEFAULT_THB | B19: จ่ายเงิน | C19: 35 | D19: ค่าธรรมเนียมโอนตั้งต้น | E19: AC
A20: BANK_FEE_BORNE_BY | B20: จ่ายเงิน | C20: OUR | D20: ใครรับภาระค่าธรรมเนียมโดยปกติ | E20: AC | F20: OUR หรือ SUPPLIER
A21: FILE_MAX_SIZE_MB | B21: ไฟล์ | C21: 20 | D21: ขนาดไฟล์สูงสุดที่รับ | E21: IT | F21: กฎ V5
A22: IMAGE_RESIZE_LONG_EDGE_PX | B22: ไฟล์ | C22: 1600 | D22: ย่อรูปด้านยาวเหลือกี่พิกเซลก่อนอัพ | E22: IT | F22: ลดพื้นที่ ~94%
A23: IMAGE_JPEG_QUALITY | B23: ไฟล์ | C23: 0.75 | D23: คุณภาพ JPEG หลังบีบอัด | E23: IT
A24: SCAN_DPI_RECOMMENDED | B24: ไฟล์ | C24: 200 | D24: ตั้งค่าเครื่องสแกน (dpi, เฉดเทา) | E24: IT + ธุรการ | F24: ลดจาก 300 dpi สี
A25: DOC_VERSIONS_KEEP | B25: ไฟล์ | C25: 3 | D25: เก็บกี่เวอร์ชันล่าสุด (ฉบับที่อนุมัติเก็บเสมอ) | E25: IT
A26: DOC_VERSION_PURGE_DAYS | B26: ไฟล์ | C26: 90 | D26: ลบเวอร์ชันเกินโควตาหลังกี่วัน | E26: IT
A27: ARCHIVE_AFTER_MONTHS | B27: ไฟล์ | C27: 12 | D27: PO ปิดเกินกี่เดือนจึงย้ายเข้าคลัง | E27: AC
A28: DOC_RETENTION_YEARS | B28: ไฟล์ | C28: 5 | D28: เก็บเอกสารกี่ปีตามกฎหมายบัญชี | E28: AC + ที่ปรึกษากฎหมาย | F28: ต้องยืนยันว่าใช้กับทุกประเภทเอกสาร
A29: QUIET_HOURS_START | B29: แจ้งเตือน | C29: 20:00 | D29: เริ่มเวลาเงียบ | E29: หัวหน้าทุกแผนก
A30: QUIET_HOURS_END | B30: แจ้งเตือน | C30: 07:00 | D30: จบเวลาเงียบ | E30: หัวหน้าทุกแผนก
A31: DAILY_DIGEST_TIME | B31: แจ้งเตือน | C31: 08:30 | D31: เวลาส่งสรุปรายวัน | E31: หัวหน้าทุกแผนก
A32: NOTIF_DEDUPE_HOURS | B32: แจ้งเตือน | C32: 24 | D32: เรื่องเดิมไม่เด้งซ้ำภายในกี่ชั่วโมง | E32: IT
A33: NOTIF_BATCH_THRESHOLD | B33: แจ้งเตือน | C33: 3 | D33: เกินกี่เรื่องใน 10 นาทีจึงรวมเป็นข้อความเดียว | E33: IT
A34: NOTIF_RETRY_MAX | B34: แจ้งเตือน | C34: 5 | D34: ลองส่งซ้ำสูงสุดกี่ครั้งก่อนตกไปที่อีเมล | E34: IT | F34: 1 → 5 → 25 นาที
A35: SYNC_INTERVAL_MINUTES | B35: เชื่อมต่อ B1 | C35: 30 | D35: ดึงข้อมูลธุรกรรมจาก B1 ทุกกี่นาที | E35: IT + ผู้ดูแล B1
A36: SYNC_MASTER_TIME | B36: เชื่อมต่อ B1 | C36: 02:00 | D36: ดึงข้อมูล master (ผู้ขาย/สินค้า) ตอนกี่โมง | E36: IT + ผู้ดูแล B1
A37: SYNC_OVERLAP_DAYS | B37: เชื่อมต่อ B1 | C37: 1 | D37: ย้อนดึงซ้ำกี่วันกันตกหล่น | E37: IT | F37: UpdateDate ของ B1 เก็บระดับวัน
A38: SYNC_STALE_WARN_MINUTES | B38: เชื่อมต่อ B1 | C38: 90 | D38: ข้อมูลเก่ากว่ากี่นาทีจึงขึ้นแบนเนอร์เตือน | E38: IT
A39: ISSUE_ACK_SLA_HOURS | B39: แจ้งบั๊ก | C39: 8 | D39: IT ต้องรับเรื่องภายในกี่ชั่วโมงทำการ | E39: IT
A40: DRIVE_ROOT_NAME | B40: ไฟล์และไดรฟ์ | C40: MGS-Documents | D40: ชื่อ Shared drive กลางที่เดียวของทั้งบริษัท | E40: IT | F40: ย้ายไดรฟ์ = ย้ายไฟล์ทั้งระบบ ต้องวางแผนก่อน
A41: CASH_LIMIT | B41: ซื้อเงินสด | C41: 50,000 | D41: เพดานยอดซื้อเงินสดต่อรายการ เกินกว่านี้ต้องเปิด PO (กฎ C4) | E41: ผู้บริหาร + AC | F41: ตั้งไว้เท่าวงเงินอนุมัติจ่าย — ยังไม่มีใครยืนยัน
...

Sheet เชื่อมต่อ B1
A1: เชื่อมต่อ SAP Business One
A2: อ่านอย่างเดียว ไม่เขียนกลับ · ตัวส่งข้อมูลรันในออฟฟิศแล้วผลักออกมา ไม่ต้องเปิดพอร์ตเข้า
A4: ข้อมูลในระบบเรา | B4: ตารางใน B1 | C4: ฟิลด์ที่ใช้ | D4: ใช้ทำอะไร | E4: ความถี่ | F4: คีย์จับคู่ | G4: หมายเหตุของทีม
A5: PO (หัวเอกสาร) | B5: OPOR | C5: DocEntry, DocNum, CardCode, CardName, DocDate, DocDueDate, DocTotal, DocCur, GroupNum, DocStatus, CANCELED, UpdateDate | D5: เลข PO · ผู้ขาย · มูลค่า · เงื่อนไขชำระ | E5: ทุก 30 นาที | F5: DocEntry
A6: PO (บรรทัด) | B6: POR1 | C6: LineNum, ItemCode, Dscription, Quantity, unitMsr, Price, LineTotal, OpenQty, WhsCode | D6: สินค้า จำนวน หน่วย · OpenQty บอกว่ายังค้างรับเท่าไหร่ | E6: ทุก 30 นาที | F6: DocEntry + LineNum
A7: ผู้ขาย | B7: OCRD | C7: CardCode, CardName, LicTradNum, E_Mail, Phone1, Currency (CardType='S') | D7: ชื่อผู้ขายสะกดตรงกันทุกใบ + อีเมลส่งสลิป | E7: ทุกคืน | F7: CardCode
A8: สินค้า | B8: OITM | C8: ItemCode, ItemName, InvntryUom, ItmsGrpCod | D8: ยืนยันว่ารหัสสินค้าเปิดใน B1 แล้วจริง | E8: ทุกคืน | F8: ItemCode
A9: ใบรับสินค้า (GRPO) | B9: OPDN / PDN1 | C9: DocNum, DocDate · ItemCode, Quantity, BaseEntry, BaseLine, BaseType | D9: BaseType = 22 คือโยงกลับไปใบสั่งซื้อ | E9: ทุก 30 นาที | F9: DocEntry + LineNum | G9: BaseType 22=PO, 20=GRPO, 18=A/P Invoice
A10: ใบแจ้งหนี้ผู้ขาย | B10: OPCH / PCH1 | C10: DocNum, NumAtCard, DocDate, DocTotal, VatSum · BaseEntry, BaseType | D10: NumAtCard = เลขใบแจ้งหนี้ของผู้ขาย ใช้ตรวจ 3 ทาง + กันรับซ้ำ | E10: ทุก 30 นาที | F10: DocEntry
A11: การจ่ายเงินออก | B11: OVPM / VPM2 | C11: DocNum, DocDate, TrsfrSum, TrsfrRef, TrsfrDate, TrsfrAcct · ใบแจ้งหนี้ที่จ่าย | D11: เทียบกับที่บันทึกในระบบเรา — เจอทันทีถ้าไม่ตรง | E11: ทุก 30 นาที | F11: DocEntry | G11: ของแถมที่มีค่ามาก วันนี้ไม่มีใครเห็น
A12: เงื่อนไขชำระ | B12: OCTG | C12: GroupNum, PymntGroup, ExtraDays, ExtraMonth, NumOfInst, StartFrom | D12: แปลงเป็นงวดจ่ายอัตโนมัติ — งวดในระบบไม่มีทางไม่ตรงกับสัญญา | E12: ทุกคืน | F12: GroupNum | G12: ขอรายการที่ใช้จริงจากผู้ดูแล B1
A14: ไม่ดึงข้อมูลเหล่านี้ (ตั้งใจไม่ขอ เพื่อให้อนุมัติสิทธิ์ผ่านง่าย)
A15: • บัญชีแยกประเภท (OJDT / JDT1)
A16: • ต้นทุนสินค้า
A17: • ข้อมูลลูกค้า
A18: • ข้อมูลพนักงาน / เงินเดือน
A20: กฎการซิงก์
A21: • Upsert ด้วย DocEntry ของ B1 ไม่ใช่ insert — ดึงซ้ำกี่ครั้งก็ไม่เกิดข้อมูลซ้ำ
A22: • ดึงเฉพาะที่ UpdateDate เปลี่ยน + ย้อนซ้ำ 1 วันกันตกหล่น (UpdateDate ของ B1 เก็บระดับวัน)
A23: • ไฟล์ไม่ครบ = ข้ามรอบ ไม่เขียนทับของเดิม — ข้อมูลเก่าที่ถูกต้องดีกว่าข้อมูลใหม่ที่พัง
A24: • ผู้ใช้ฐานข้อมูลมีสิทธิ์ SELECT เท่านั้น จำกัดเฉพาะ 7 ตารางข้างบน
A25: • บันทึกทุกรอบใน Sync_Log · ตรวจนับรายวันว่าจำนวน PO เปิดอยู่ตรงกับ B1
A26: • B1 ล่ม = ระบบยังใช้ได้ ขึ้นป้ายบอกว่าข้อมูลเก่าแค่ไหน ไม่บล็อกการทำงาน
A28: ยังไม่ทราบ: B1 รุ่นย่อย (9.x / 10.0) และฐานข้อมูลเป็น MS SQL หรือ HANA — ตัดสินว่าจะใช้ Service Layer (10.0 ขึ้นไป) หรืออ่าน SQL แบบ read-only (ได้ทุกรุ่น)

Sheet ประเด็นค้าง
A1: ประเด็นที่ต้องตัดสินใจก่อนขึ้นระบบ
A2: รวบรวมจากทุกเอกสาร · ช่อง «คำตอบของทีม» และ «สถานะ» กรอกได้เลย — นี่คือแท็บที่ควรเปิดก่อนแท็บอื่น
A4: # | B4: หมวด | C4: ประเด็น | D4: ค่าที่ผมตั้งไว้ก่อน | E4: ใครตัดสิน | F4: คำตอบของทีม | G4: สถานะ | H4: ความสำคัญ
A5: 1 | B5: เชื่อมต่อ B1 | C5: B1 รุ่นย่อยอะไร (9.x / 10.0) และฐานข้อมูล MS SQL หรือ HANA | D5: ยังไม่ทราบ | E5: ผู้ดูแล B1 | G5: รอตัดสินใจ | H5: สูง
A6: 2 | B6: เชื่อมต่อ B1 | C6: ใครดูแล B1 และขอสิทธิ์อ่าน 7 ตารางต้องผ่านใคร | D6: ยังไม่ทราบ | E6: IT + ผู้บริหาร | G6: รอตัดสินใจ | H6: สูง
A7: 3 | B7: เชื่อมต่อ B1 | C7: มี job ส่งออกข้อมูลจาก B1 อยู่แล้วหรือไม่ (B1if / Crystal / SQL Agent) | D7: ยังไม่ทราบ | E7: ผู้ดูแล B1 | G7: รอตัดสินใจ | H7: กลาง
A8: 4 | B8: เชื่อมต่อ B1 | C8: รายการเงื่อนไขชำระ (OCTG) ที่บริษัทใช้จริงมีกี่แบบ | D8: ยังไม่ทราบ | E8: AC + ผู้ดูแล B1 | G8: รอตัดสินใจ | H8: สูง
A9: 5 | B9: เชื่อมต่อ B1 | C9: มีเครื่องในออฟฟิศที่เปิดตลอดและรัน scheduled task ได้หรือไม่ | D9: ยังไม่ทราบ | E9: IT | G9: รอตัดสินใจ | H9: สูง
A10: 6 | B10: เชื่อมต่อ B1 | C10: ตารางงวดชำระต่อเอกสารใน B1 ชื่ออะไรในรุ่นที่ใช้ | D10: ยังไม่ยืนยัน | E10: ผู้ดูแล B1 | G10: รอตัดสินใจ | H10: กลาง
A11: 7 | B11: ซื้อเงินสด | C11: เพดานยอดซื้อเงินสดต่อรายการควรเป็นเท่าไหร่ | D11: 50,000 บาท | E11: ผู้บริหาร + AC | G11: รอตัดสินใจ | H11: สูง
A12: 8 | B12: ซื้อเงินสด | C12: ใครมีสิทธิ์อนุมัติการข้าม QC — หัวหน้า QC เท่านั้น หรือจัดซื้อระบุเองได้ | D12: จัดซื้อระบุเอง แล้วหัวหน้า QC เห็นย้อนหลังทุกใบ | E12: หัวหน้า QC | G12: รอตัดสินใจ | H12: สูง
A13: 9 | B13: ซื้อเงินสด | C13: เงินสดที่พนักงานสำรองจ่าย ต้องมีสายอนุมัติเบิกคืนแยกหรือไม่ | D13: ยังไม่ทำ — บันทึกไว้เฉย ๆ | E13: AC | G13: รอตัดสินใจ | H13: กลาง
A14: 10 | B14: รวมไฟล์ | C14: ต้องเก็บไฟล์ต้นฉบับตามกฎหมายกี่ปี หรือเก็บไฟล์รวมพอ | D14: เก็บต้นฉบับ 90 วันหลังรวมเล่มแล้วลบ | E14: AC + ผู้สอบบัญชี | G14: รอตัดสินใจ | H14: สูง
A15: 11 | B15: รวมไฟล์ | C15: ไฟล์รวมต้องใส่รหัสผ่านหรือลายน้ำ «สำเนา» หรือไม่ | D15: ไม่ใส่ | E15: AC | G15: รอตัดสินใจ | H15: ต่ำ
A16: 12 | B16: ขอทำจ่าย | C16: ข้อความที่ประทับลงเอกสารต้องมีลายเซ็นดิจิทัลหรือ QR ตรวจสอบหรือไม่ | D16: ข้อความอย่างเดียว ไม่มี QR | E16: AC + ผู้สอบบัญชี | G16: รอตัดสินใจ | H16: กลาง
... A45: 41 | B45: โครงสร้าง | C45: ตาราง Price_Requests / Quotations ที่เพิ่งเพิ่ม ตรงกับวิธีขอราคาจริงไหม | D45: ตามที่ร่างไว้ | E45: SR | G45: รอตัดสินใจ | H45: สูง
B47: รวมประเด็นทั้งหมด | D47: =COUNTA(C5:C45)
B48: รอตัดสินใจ | D48: =COUNTIF(G5:G45,"รอตัดสินใจ")
B49: ตัดสินใจแล้ว | D49: =COUNTIF(G5:G45,"ตัดสินใจแล้ว")
B50: ความสำคัญสูง ที่ยังรอตัดสินใจ | D50: =COUNTIFS(H5:H45,"สูง",G5:G45,"รอตัดสินใจ")
B52: ทุกค่าในคอลัมน์ «ค่าที่ผมตั้งไว้ก่อน» เป็นค่าที่ผมเลือกเองเพื่อให้ระบบเดินได้ ไม่ได้มาจากนโยบายของบริษัท — ถ้าไม่แก้ ระบบจะใช้ค่าเหล่านี้จริงตอนขึ้นใช้งาน
